Workbook

Sheet Instructions
B2: THE WEALTH DRAIN — RETIREMENT TOOLKIT
B3: Updated for 2026 Tax Year
B5: WELCOME
B7: HOW TO USE THIS TOOLKIT
B8: This workbook contains 6 tabs. Each one is a standalone tool, but they also work together — your inputs on the Reference Data tab feed into every other sheet automatically.
B10: Step 1: Start with the Reference Data tab
B11: Enter your personal details (age, income, filing status, state). These flow into every calculator in the workbook. The 2026 federal tax brackets and Social Security figures are pre-loaded — you only need to update them once a year (instructions below).
B13: Step 2: Explore each tab
B14: • Retirement Readiness Scorecard — Your overall financial health dashboard. Grades your savings rate, projects your freedom number, and shows where you stand.
B15: • Fee Drain Analyzer — Compare up to 4 funds side-by-side. See exactly how much fees cost you over your investment timeline.
B16: • Roth Conversion Planner — Model year-by-year Roth conversions and see the tax impact of different conversion amounts.
B17: • Social Security Optimizer — Compare claiming at 62, 67, and 70. Find your break-even age and see lifetime benefit projections.
... B43: YouTube: youtube.com/@TheQuietDrain

Sheet Reference Data
B2: REFERENCE DATA & PERSONAL INPUTS
B3: All blue/yellow cells are editable. These values feed every tab in the workbook.
B5: YOUR PERSONAL INFORMATION
B6: Current Age | C6: 30
B7: Retirement Age (Target) | C7: 65
B8: Annual Gross Income ($) | C8: 75000
B9: Filing Status | C9: Single
B10: State | C10: No State Income Tax
B11: Current Retirement Savings ($) | C11: 50000
B12: Monthly Contribution ($) | C12: 1250
B13: Employer Match (%) | C13: 0.03
B14: Expected Annual Return (%) | C14: 0.08
B15: Expected Inflation (%) | C15: 0.03
B16: Annual Expenses in Retirement ($) | C16: 48000
B17: Filing Status options: Single, Married Filing Jointly, Married Filing Separately, Head of Household
B19: 2026 FEDERAL TAX BRACKETS (Single)
B20: Tax Rate | C20: From ($) | D20: To ($) | E20: Notes
B21: 0.1 | C21: 0 | D21: 11925
B22: 0.12 | C22: 11926 | D22: 48475
B23: 0.22 | C23: 48476 | D23: 103350
B24: 0.24 | C24: 103351 | D24: 197300
B25: 0.32 | C25: 197301 | D25: 250525
B26: 0.35 | C26: 250526 | D26: 626350
B27: 0.37 | C27: 626351 | D27: 99999999 | E27: Top bracket
B29: Standard Deduction (2026) | C29: 15700
B31: SOCIAL SECURITY REFERENCE (2026)
B32: Full Retirement Age (FRA) | C32: 67 | E32: Born 1960 or later
B33: Max Monthly Benefit at FRA | C33: 4018 | E33: 2026 figure
B34: Early Claiming Age | C34: 62
B35: Early Claiming Reduction (%) | C35: 0.3 | E35: 30% reduction at 62 if FRA is 67
B36: Delayed Retirement Credits (%/yr) | C36: 0.08 | E36: 8% per year past FRA up to 70
B37: COLA Estimate (%) | C37: 0.025 | E37: Historical average ~2-3%
B38: Earnings Test Limit (under FRA) | C38: 23400 | E38: 2026 limit
B39: First Bend Point ($) | C39: 1226 | E39: 2026 PIA formula
B40: Second Bend Point ($) | C40: 7391 | E40: 2026 PIA formula
B43: LAST UPDATED: January 2026
B44: Next update needed: October/November 2026 (when IRS releases 2027 brackets)

Sheet Readiness Scorecard
B2: RETIREMENT READINESS SCORECARD
B3: Your financial health at a glance. All data pulls from the Reference Data tab.
B5: KEY METRICS
B6: Years to Retirement | C6: ='Reference Data'!C7-'Reference Data'!C6 -> 35
B7: Annual Contribution ($) | C7: ='Reference Data'!C12*12 -> 15000
B8: Employer Match Contribution ($) | C8: ='Reference Data'!C8*'Reference Data'!C13 -> 2250
B9: Total Annual Savings ($) | C9: =C7+C8 -> 17250
B11: SAVINGS RATE GRADE
B12: Savings Rate | C12: =C9/'Reference Data'!C8 -> 0.23 | D12: Grade: | E12: =IF(C12>=0.25,"A — Excellent",IF(C12>=0.2,"B — Great",IF(C12>=0.15,"C — Good",IF(C12>=0.1,"D — Needs Work","F — Critical")))) -> B — Great
B13: Target: 20%+ of gross income for on-track retirement
B15: YOUR FREEDOM NUMBER
B16: Annual Expenses in Retirement | C16: ='Reference Data'!C16 -> 48000
B17: Freedom Number (25x expenses) | C17: =C16*25 -> 1200000 | E17: Based on the 4% rule
B19: Projected Portfolio at Retirement | C19: =FV('Reference Data'!C14,C6,-C9,-'Reference Data'!C11) -> 3711732.1
B20: Gap to Freedom Number | C20: =C19-C17 -> 2511732.1 | D20: Status: | E20: =IF(C20>=0,"ON TRACK","BEHIND — Increase savings or timeline") -> ON TRACK
B22: PASSIVE INCOME PROJECTION
B23: Monthly Freedom Income (4% rule) | C23: =C19*0.04/12 -> 12372.44
B24: Yearly Passive Cashflow | C24: =C19*0.04 -> 148469.28
B25: Covers Monthly Expenses? | C25: =C16/12 -> 4000 | D25: Need/mo | E25: =IF(C23>=C25,"YES — Fully funded","NO — Shortfall of "&TEXT(C25-C23,"$#,##0")&"/mo") -> YES — Fully funded
B27: COMPOUND INTEREST MILESTONES
B28: Years to $100K | C28: =IFERROR(NPER('Reference Data'!C14,-(C9),-('Reference Data'!C11),100000),"Already there!") -> 2.2409944 | E28: The $100K barrier — after this, compounding accelerates
B29: Years to $500K | C29: =IFERROR(NPER('Reference Data'!C14,-(C9),-('Reference Data'!C11),500000),"Already there!") -> 12.877564
B30: Years to $1,000,000 | C30: =IFERROR(NPER('Reference Data'!C14,-(C9),-('Reference Data'!C11),1000000),"Already there!") -> 19.762312
B31: Years to Freedom Number | C31: =IFERROR(NPER('Reference Data'!C14,-(C9),-('Reference Data'!C11),C17),"Already there!") -> 21.741401 | E31: =IF(ISNUMBER(C31),"You'll hit freedom at age "&TEXT('Reference Data'!C6+C31,"0"),"") -> You'll hit freedom at age 52

Sheet Fee Drain Analyzer
B2: FEE DRAIN ANALYZER
B3: See how much fees silently eat from your portfolio. Compare up to 4 funds.
B5: FUND COMPARISON
C6: Fund A | D6: Fund B | E6: Fund C | F6: Fund D
B7: Fund Name | C7: VTI (Total Market) | D7: VFIAX (S&P 500) | E7: Growth Fund X | F7: Managed Fund Y
B8: Expense Ratio (%) | C8: 0.0003 | D8: 0.0004 | E8: 0.0075 | F8: 0.01
B9: Annual Return (%) | C9: 0.08 | D9: 0.08 | E9: 0.08 | F9: 0.08
B10: Initial Investment ($) | C10: 50000
B11: Annual Addition ($) | C11: 15000
B12: Time Horizon (Years) | C12: 30
B14: RESULTS
C15: =B7 -> Fund Name | D15: =B7 -> Fund Name | E15: =B7 -> Fund Name | F15: =B7 -> Fund Name
B16: Final Balance ($) | C16: =FV(C9-C8,$C$12,-$C$11,-$C$10) -> 2188882.6 | D16: =FV(D9-D8,$C$12,-$C$11,-$C$10) -> 2184403 | E16: =FV(E9-E8,$C$12,-$C$11,-$C$10) -> 1890484.3 | F16: =FV(F9-F8,$C$12,-$C$11,-$C$10) -> 1797524.5
B17: Balance Without Fees ($) | C17: =FV(C9,$C$12,-$C$11,-$C$10) -> 2202381 | D17: =FV(D9,$C$12,-$C$11,-$C$10) -> 2202381 | E17: =FV(E9,$C$12,-$C$11,-$C$10) -> 2202381 | F17: =FV(F9,$C$12,-$C$11,-$C$10) -> 2202381
B18: MONEY LOST TO FEES ($) | C18: =C17-C16 -> 13498.446 | D18: =D17-D16 -> 17977.966 | E18: =E17-E16 -> 311896.7 | F18: =F17-F16 -> 404856.46
B19: % of Wealth Lost to Fees | C19: =IFERROR(C18/C17,0) -> 0.0061290238 | D19: =IFERROR(D18/D17,0) -> 0.0081629681 | E19: =IFERROR(E18/E17,0) -> 0.14161796 | F19: =IFERROR(F18/F17,0) -> 0.18382671
B20: Effective Net Return | C20: =C9-C8 -> 0.0797 | D20: =D9-D8 -> 0.0796 | E20: =E9-E8 -> 0.0725 | F20: =F9-F8 -> 0.07
B22: YEAR-BY-YEAR: LOWEST FEE vs HIGHEST FEE
B23: Year | C23: Low-Fee Balance | D23: High-Fee Balance | E23: Cumulative Fee Drain | F23: Fee Drain This Year | G23: Lost as % of Total
B24: 0 | C24: =$C$10 -> 50000 | D24: =$C$10 -> 50000 | E24: =C24-D24 -> 0 | F24: =IF(B24=0,0,E24-E24) -> 0 | G24: =IFERROR(E24/C24,0) -> 0
B25: 1 | C25: =(C24+$C$11)*(1+$C$9-$C$8) -> 70180.5 | D25: =(D24+$C$11)*(1+$F$9-$F$8) -> 69550 | E25: =C25-D25 -> 630.5 | F25: =IF(B25=0,0,E25-E24) -> 630.5 | G25: =IFERROR(E25/C25,0) -> 0.008983977
B26: 2 | C26: =(C25+$C$11)*(1+$C$9-$C$8) -> 91969.386 | D26: =(D25+$C$11)*(1+$F$9-$F$8) -> 90468.5 | E26: =C26-D26 -> 1500.8859 | F26: =IF(B26=0,0,E26-E25) -> 870.38585 | G26: =IFERROR(E26/C26,0) -> 0.016319407
B27: 3 | C27: =(C26+$C$11)*(1+$C$9-$C$8) -> 115494.85 | D27: =(D26+$C$11)*(1+$F$9-$F$8) -> 112851.29 | E27: =C27-D27 -> 2643.5509 | F27: =IF(B27=0,0,E27-E26) -> 1142.6651 | G27: =IFERROR(E27/C27,0) -> 0.022888908
B28: 4 | C28: =(C27+$C$11)*(1+$C$9-$C$8) -> 140895.29 | D28: =(D27+$C$11)*(1+$F$9-$F$8) -> 136800.89 | E28: =C28-D28 -> 4094.3995 | F28: =IF(B28=0,0,E28-E27) -> 1450.8486 | G28: =IFERROR(E28/C28,0) -> 0.029059876
B29: 5 | C29: =(C28+$C$11)*(1+$C$9-$C$8) -> 168320.14 | D29: =(D28+$C$11)*(1+$F$9-$F$8) -> 162426.95 | E29: =C29-D29 -> 5893.1917 | F29: =IF(B29=0,0,E29-E28) -> 1798.7922 | G29: =IFERROR(E29/C29,0) -> 0.035011804
B30: 6 | C30: =(C29+$C$11)*(1+$C$9-$C$8) -> 197930.75 | D30: =(D29+$C$11)*(1+$F$9-$F$8) -> 189846.83 | E30: =C30-D30 -> 8083.9205 | F30: =IF(B30=0,0,E30-E29) -> 2190.7288 | G30: =IFERROR(E30/C30,0) -> 0.040842165
B31: 7 | C31: =(C30+$C$11)*(1+$C$9-$C$8) -> 229901.34 | D31: =(D30+$C$11)*(1+$F$9-$F$8) -> 219186.11 | E31: =C31-D31 -> 10715.223 | F31: =IF(B31=0,0,E31-E30) -> 2631.3028 | G31: =IFERROR(E31/C31,0) -> 0.046607921
B32: 8 | C32: =(C31+$C$11)*(1+$C$9-$C$8) -> 264419.97 | D32: =(D31+$C$11)*(1+$F$9-$F$8) -> 250579.14 | E32: =C32-D32 -> 13840.832 | F32: =IF(B32=0,0,E32-E31) -> 3125.6086 | G32: =IFERROR(E32/C32,0) -> 0.052344124
B33: 9 | C33: =(C32+$C$11)*(1+$C$9-$C$8) -> 301689.74 | D33: =(D32+$C$11)*(1+$F$9-$F$8) -> 284169.68 | E33: =C33-D33 -> 17520.064 | F33: =IF(B33=0,0,E33-E32) -> 3679.232 | G33: =IFERROR(E33/C33,0) -> 0.058073117
B34: 10 | C34: =(C33+$C$11)*(1+$C$9-$C$8) -> 341929.92 | D34: =(D33+$C$11)*(1+$F$9-$F$8) -> 320111.56 | E34: =C34-D34 -> 21818.359 | F34: =IF(B34=0,0,E34-E33) -> 4298.295 | G34: =IFERROR(E34/C34,0) -> 0.063809447
B35: 11 | C35: =(C34+$C$11)*(1+$C$9-$C$8) -> 385377.23 | D35: =(D34+$C$11)*(1+$F$9-$F$8) -> 358569.37 | E35: =C35-D35 -> 26807.864 | F35: =IF(B35=0,0,E35-E34) -> 4989.5053 | G35: =IFERROR(E35/C35,0) -> 0.069562657
B36: 12 | C36: =(C35+$C$11)*(1+$C$9-$C$8) -> 432287.3 | D36: =(D35+$C$11)*(1+$F$9-$F$8) -> 399719.22 | E36: =C36-D36 -> 32568.074 | F36: =IF(B36=0,0,E36-E35) -> 5760.2096 | G36: =IFERROR(E36/C36,0) -> 0.075338956
... B54: 30 | C54: =(C53+$C$11)*(1+$C$9-$C$8) -> 2323569.6 | D54: =(D53+$C$11)*(1+$F$9-$F$8) -> 1896708.4 | E54: =C54-D54 -> 426861.27 | F54: =IF(B54=0,0,E54-E53) -> 47434.752 | G54: =IFERROR(E54/C54,0) -> 0.18370926

Sheet Roth Conversion Planner
B2: ROTH CONVERSION PLANNER
B3: Model the tax impact of converting Traditional IRA/401k funds to Roth.
B5: CONVERSION INPUTS
B6: Traditional IRA Balance ($) | C6: 200000
B7: Other Taxable Income ($) | C7: 60000
B8: Annual Conversion Amount ($) | C8: 30000
B9: Years to Convert Over | C9: 5
B10: Expected Return During Conversion (%) | C10: 0.07
B11: Tax Rate in Retirement (est.) (%) | C11: 0.22
B12: Current Marginal Tax Rate (%) | C12: 0.24
B14: SCENARIO COMPARISON
C15: No Conversion | D15: Partial Conversion | E15: Full Conversion
B16: Starting Balance | C16: =C6 -> 200000 | D16: =C6 -> 200000 | E16: =C6 -> 200000
B17: Amount Converted | C17: 0 | D17: =C8*C9 -> 150000 | E17: =C6 -> 200000
B18: Tax Paid on Conversion | C18: 0 | D18: =D17*C12 -> 36000 | E18: =E17*C12 -> 48000
B19: Remaining Trad. IRA (after convert) | C19: =C6 -> 200000 | D19: =C6-D17 -> 50000 | E19: 0
B20: Roth Balance (grows tax-free) | C20: 0 | D20: =D17-D18 -> 114000 | E20: =C6-E18 -> 152000
B21: Trad. IRA After Growth (20yr) | C21: =C19*(1+C10)^20 -> 773936.89 | D21: =D19*(1+C10)^20 -> 193484.22 | E21: 0
B22: Roth After Growth (20yr) | C22: 0 | D22: =D20*(1+C10)^20 -> 441144.03 | E22: =E20*(1+C10)^20 -> 588192.04
B23: Tax on Trad. Withdrawal | C23: =C21*C11 -> 170266.12 | D23: =D21*C11 -> 42566.529 | E23: 0
B24: NET After-Tax Total | C24: =C21-C23 -> 603670.78 | D24: =(D21-D23)+D22 -> 592061.72 | E24: =E22 -> 588192.04
B25: TAX SAVINGS vs No Conversion | C25: 0 | D25: =D24-C24 -> -11609.053 | E25: =E24-C24 -> -15478.738
B27: WHEN ROTH CONVERSION MAKES SENSE:
B28: • Your current tax rate is LOWER than your expected retirement tax rate
B29: • You expect tax rates to increase in the future (e.g., TCJA sunset after 2025)
B30: • You have a low-income year (job change, sabbatical, early retirement gap)
B31: • You want to reduce future Required Minimum Distributions (RMDs)
B32: • You want to leave tax-free assets to heirs

Sheet Social Security Optimizer
B2: SOCIAL SECURITY OPTIMIZER
B3: Compare claiming ages and find your break-even point.
B5: YOUR SOCIAL SECURITY INPUTS
B6: Estimated Monthly Benefit at FRA ($) | C6: 2500
B7: Current Age | C7: 55
B8: Life Expectancy | C8: 85
B9: COLA Assumption (%) | C9: 0.025
B11: CLAIMING AGE COMPARISON
C12: Claim at 62 | D12: Claim at 67 (FRA) | E12: Claim at 70
B13: Monthly Benefit (starting) | C13: =C6*0.7 -> 1750 | D13: =C6 -> 2500 | E13: =C6*1.24 -> 3100
B14: Annual Benefit (starting) | C14: =C13*12 -> 21000 | D14: =D13*12 -> 30000 | E14: =E13*12 -> 37200
B15: Reduction/Increase (%) | C15: -0.3 | D15: 0 | E15: 0.24
B16: Total Collected by Age 75 | C16: =IF(75>=62,C14*((1+$C$9)^13-1)/$C$9,0) -> 317949.28 | D16: =IF(75>=67,D14*((1+$C$9)^8-1)/$C$9,0) -> 262083.48 | E16: =IF(75>=70,E14*((1+$C$9)^5-1)/$C$9,0) -> 195535.42
B17: Total Collected by Age 80 | C17: =IF(80>=62,C14*((1+$C$9)^18-1)/$C$9,0) -> 470113.32 | D17: =IF(80>=67,D14*((1+$C$9)^13-1)/$C$9,0) -> 454213.25 | E17: =IF(80>=70,E14*((1+$C$9)^10-1)/$C$9,0) -> 416765.8
B18: Total Collected by Age 85 | C18: =IF(85>=62,C14*((1+$C$9)^23-1)/$C$9,0) -> 642272.97 | D18: =IF(85>=67,D14*((1+$C$9)^18-1)/$C$9,0) -> 671590.46 | E18: =IF(85>=70,E14*((1+$C$9)^15-1)/$C$9,0) -> 667067.67
B19: Total Collected by Age 90 | C19: =IF(90>=62,C14*((1+$C$9)^28-1)/$C$9,0) -> 837055.82 | D19: =IF(90>=67,D14*((1+$C$9)^23-1)/$C$9,0) -> 917532.82 | E19: =IF(90>=70,E14*((1+$C$9)^20-1)/$C$9,0) -> 950261.26
B20: TOTAL LIFETIME (to life expectancy) | C20: =IF($C$8>=62,C14*((1+$C$9)^($C$8-62)-1)/$C$9,0) -> 642272.97 | D20: =IF($C$8>=67,D14*((1+$C$9)^($C$8-67)-1)/$C$9,0) -> 671590.46 | E20: =IF($C$8>=70,E14*((1+$C$9)^($C$8-70)-1)/$C$9,0) -> 667067.67
B22: BEST CLAIMING STRATEGY: | C22: =IF(AND(E20>=D20,E20>=C20),"Claim at 70 — Maximum lifetime benefit",IF(AND(D20>=C20,D20>=E20),"Claim at 67 (FRA) — Balanced approach","Claim at 62 — Only if you need income now or have shorter life expectancy")) -> Claim at 67 (FRA) — Balanced approach
B24: BREAK-EVEN ANALYSIS
B25: 62 vs 67 Break-Even Age | C25: =IFERROR(62+(C14*5)/(D14-C14),"N/A") -> 73.666667
B26: 67 vs 70 Break-Even Age | C26: =IFERROR(67+(D14*3)/(E14-D14),"N/A") -> 79.5
B27: If you live past the break-even age, waiting was the better choice.

Sheet Full Retirement Projection
B2: FULL RETIREMENT PROJECTION
B3: Year-by-year timeline from now through retirement, showing contributions, growth, withdrawals, and taxes. | H3: Annual Fee Rate (%) | I3: 0.005
H4: Withdrawal Rate in Retirement (%) | I4: 0.04
B5: Year | C5: Age | D5: Contribution | E5: Employer Match | F5: Growth | G5: Fees Paid | H5: Withdrawal | I5: Tax on Withdrawal | J5: Net Cashflow | K5: Portfolio Balance
B6: =YEAR(TODAY())+0 -> 2026 | C6: ='Reference Data'!C6+0 -> 30 | D6: =IF(C6<'Reference Data'!$C$7,'Readiness Scorecard'!$C$7,0) -> 15000 | E6: =IF(C6<'Reference Data'!$C$7,'Readiness Scorecard'!$C$8,0) -> 2250 | F6: ='Reference Data'!C11*'Reference Data'!$C$14 -> 4000 | G6: ='Reference Data'!C11*$I$3 -> 250 | H6: =IF(C6>='Reference Data'!$C$7,'Reference Data'!C11*$I$4,0) -> 0 | I6: =H6*0.22 -> 0 | J6: =H6-I6 -> 0 | K6: ='Reference Data'!C11+D6+E6+F6-G6-H6 -> 71000
B7: =YEAR(TODAY())+1 -> 2027 | C7: ='Reference Data'!C6+1 -> 31 | D7: =IF(C7<'Reference Data'!$C$7,'Readiness Scorecard'!$C$7,0) -> 15000 | E7: =IF(C7<'Reference Data'!$C$7,'Readiness Scorecard'!$C$8,0) -> 2250 | F7: =K6*'Reference Data'!$C$14 -> 5680 | G7: =K6*$I$3 -> 355 | H7: =IF(C7>='Reference Data'!$C$7,K6*$I$4,0) -> 0 | I7: =H7*0.22 -> 0 | J7: =H7-I7 -> 0 | K7: =K6+D7+E7+F7-G7-H7 -> 93575
B8: =YEAR(TODAY())+2 -> 2028 | C8: ='Reference Data'!C6+2 -> 32 | D8: =IF(C8<'Reference Data'!$C$7,'Readiness Scorecard'!$C$7,0) -> 15000 | E8: =IF(C8<'Reference Data'!$C$7,'Readiness Scorecard'!$C$8,0) -> 2250 | F8: =K7*'Reference Data'!$C$14 -> 7486 | G8: =K7*$I$3 -> 467.875 | H8: =IF(C8>='Reference Data'!$C$7,K7*$I$4,0) -> 0 | I8: =H8*0.22 -> 0 | J8: =H8-I8 -> 0 | K8: =K7+D8+E8+F8-G8-H8 -> 117843.12
B9: =YEAR(TODAY())+3 -> 2029 | C9: ='Reference Data'!C6+3 -> 33 | D9: =IF(C9<'Reference Data'!$C$7,'Readiness Scorecard'!$C$7,0) -> 15000 | E9: =IF(C9<'Reference Data'!$C$7,'Readiness Scorecard'!$C$8,0) -> 2250 | F9: =K8*'Reference Data'!$C$14 -> 9427.45 | G9: =K8*$I$3 -> 589.21563 | H9: =IF(C9>='Reference Data'!$C$7,K8*$I$4,0) -> 0 | I9: =H9*0.22 -> 0 | J9: =H9-I9 -> 0 | K9: =K8+D9+E9+F9-G9-H9 -> 143931.36
B10: =YEAR(TODAY())+4 -> 2030 | C10: ='Reference Data'!C6+4 -> 34 | D10: =IF(C10<'Reference Data'!$C$7,'Readiness Scorecard'!$C$7,0) -> 15000 | E10: =IF(C10<'Reference Data'!$C$7,'Readiness Scorecard'!$C$8,0) -> 2250 | F10: =K9*'Reference Data'!$C$14 -> 11514.509 | G10: =K9*$I$3 -> 719.6568 | H10: =IF(C10>='Reference Data'!$C$7,K9*$I$4,0) -> 0 | I10: =H10*0.22 -> 0 | J10: =H10-I10 -> 0 | K10: =K9+D10+E10+F10-G10-H10 -> 171976.21
B11: =YEAR(TODAY())+5 -> 2031 | C11: ='Reference Data'!C6+5 -> 35 | D11: =IF(C11<'Reference Data'!$C$7,'Readiness Scorecard'!$C$7,0) -> 15000 | E11: =IF(C11<'Reference Data'!$C$7,'Readiness Scorecard'!$C$8,0) -> 2250 | F11: =K10*'Reference Data'!$C$14 -> 13758.097 | G11: =K10*$I$3 -> 859.88106 | H11: =IF(C11>='Reference Data'!$C$7,K10*$I$4,0) -> 0 | I11: =H11*0.22 -> 0 | J11: =H11-I11 -> 0 | K11: =K10+D11+E11+F11-G11-H11 -> 202124.43
B12: =YEAR(TODAY())+6 -> 2032 | C12: ='Reference Data'!C6+6 -> 36 | D12: =IF(C12<'Reference Data'!$C$7,'Readiness Scorecard'!$C$7,0) -> 15000 | E12: =IF(C12<'Reference Data'!$C$7,'Readiness Scorecard'!$C$8,0) -> 2250 | F12: =K11*'Reference Data'!$C$14 -> 16169.954 | G12: =K11*$I$3 -> 1010.6221 | H12: =IF(C12>='Reference Data'!$C$7,K11*$I$4,0) -> 0 | I12: =H12*0.22 -> 0 | J12: =H12-I12 -> 0 | K12: =K11+D12+E12+F12-G12-H12 -> 234533.76
B13: =YEAR(TODAY())+7 -> 2033 | C13: ='Reference Data'!C6+7 -> 37 | D13: =IF(C13<'Reference Data'!$C$7,'Readiness Scorecard'!$C$7,0) -> 15000 | E13: =IF(C13<'Reference Data'!$C$7,'Readiness Scorecard'!$C$8,0) -> 2250 | F13: =K12*'Reference Data'!$C$14 -> 18762.701 | G13: =K12*$I$3 -> 1172.6688 | H13: =IF(C13>='Reference Data'!$C$7,K12*$I$4,0) -> 0 | I13: =H13*0.22 -> 0 | J13: =H13-I13 -> 0 | K13: =K12+D13+E13+F13-G13-H13 -> 269373.79
B14: =YEAR(TODAY())+8 -> 2034 | C14: ='Reference Data'!C6+8 -> 38 | D14: =IF(C14<'Reference Data'!$C$7,'Readiness Scorecard'!$C$7,0) -> 15000 | E14: =IF(C14<'Reference Data'!$C$7,'Readiness Scorecard'!$C$8,0) -> 2250 | F14: =K13*'Reference Data'!$C$14 -> 21549.903 | G14: =K13*$I$3 -> 1346.869 | H14: =IF(C14>='Reference Data'!$C$7,K13*$I$4,0) -> 0 | I14: =H14*0.22 -> 0 | J14: =H14-I14 -> 0 | K14: =K13+D14+E14+F14-G14-H14 -> 306826.83
B15: =YEAR(TODAY())+9 -> 2035 | C15: ='Reference Data'!C6+9 -> 39 | D15: =IF(C15<'Reference Data'!$C$7,'Readiness Scorecard'!$C$7,0) -> 15000 | E15: =IF(C15<'Reference Data'!$C$7,'Readiness Scorecard'!$C$8,0) -> 2250 | F15: =K14*'Reference Data'!$C$14 -> 24546.146 | G15: =K14*$I$3 -> 1534.1341 | H15: =IF(C15>='Reference Data'!$C$7,K14*$I$4,0) -> 0 | I15: =H15*0.22 -> 0 | J15: =H15-I15 -> 0 | K15: =K14+D15+E15+F15-G15-H15 -> 347088.84
B16: =YEAR(TODAY())+10 -> 2036 | C16: ='Reference Data'!C6+10 -> 40 | D16: =IF(C16<'Reference Data'!$C$7,'Readiness Scorecard'!$C$7,0) -> 15000 | E16: =IF(C16<'Reference Data'!$C$7,'Readiness Scorecard'!$C$8,0) -> 2250 | F16: =K15*'Reference Data'!$C$14 -> 27767.107 | G16: =K15*$I$3 -> 1735.4442 | H16: =IF(C16>='Reference Data'!$C$7,K15*$I$4,0) -> 0 | I16: =H16*0.22 -> 0 | J16: =H16-I16 -> 0 | K16: =K15+D16+E16+F16-G16-H16 -> 390370.5
B17: =YEAR(TODAY())+11 -> 2037 | C17: ='Reference Data'!C6+11 -> 41 | D17: =IF(C17<'Reference Data'!$C$7,'Readiness Scorecard'!$C$7,0) -> 15000 | E17: =IF(C17<'Reference Data'!$C$7,'Readiness Scorecard'!$C$8,0) -> 2250 | F17: =K16*'Reference Data'!$C$14 -> 31229.64 | G17: =K16*$I$3 -> 1951.8525 | H17: =IF(C17>='Reference Data'!$C$7,K16*$I$4,0) -> 0 | I17: =H17*0.22 -> 0 | J17: =H17-I17 -> 0 | K17: =K16+D17+E17+F17-G17-H17 -> 436898.29
B18: =YEAR(TODAY())+12 -> 2038 | C18: ='Reference Data'!C6+12 -> 42 | D18: =IF(C18<'Reference Data'!$C$7,'Readiness Scorecard'!$C$7,0) -> 15000 | E18: =IF(C18<'Reference Data'!$C$7,'Readiness Scorecard'!$C$8,0) -> 2250 | F18: =K17*'Reference Data'!$C$14 -> 34951.863 | G18: =K17*$I$3 -> 2184.4914 | H18: =IF(C18>='Reference Data'!$C$7,K17*$I$4,0) -> 0 | I18: =H18*0.22 -> 0 | J18: =H18-I18 -> 0 | K18: =K17+D18+E18+F18-G18-H18 -> 486915.66
B19: =YEAR(TODAY())+13 -> 2039 | C19: ='Reference Data'!C6+13 -> 43 | D19: =IF(C19<'Reference Data'!$C$7,'Readiness Scorecard'!$C$7,0) -> 15000 | E19: =IF(C19<'Reference Data'!$C$7,'Readiness Scorecard'!$C$8,0) -> 2250 | F19: =K18*'Reference Data'!$C$14 -> 38953.253 | G19: =K18*$I$3 -> 2434.5783 | H19: =IF(C19>='Reference Data'!$C$7,K18*$I$4,0) -> 0 | I19: =H19*0.22 -> 0 | J19: =H19-I19 -> 0 | K19: =K18+D19+E19+F19-G19-H19 -> 540684.33
B20: =YEAR(TODAY())+14 -> 2040 | C20: ='Reference Data'!C6+14 -> 44 | D20: =IF(C20<'Reference Data'!$C$7,'Readiness Scorecard'!$C$7,0) -> 15000 | E20: =IF(C20<'Reference Data'!$C$7,'Readiness Scorecard'!$C$8,0) -> 2250 | F20: =K19*'Reference Data'!$C$14 -> 43254.747 | G20: =K19*$I$3 -> 2703.4217 | H20: =IF(C20>='Reference Data'!$C$7,K19*$I$4,0) -> 0 | I20: =H20*0.22 -> 0 | J20: =H20-I20 -> 0 | K20: =K19+D20+E20+F20-G20-H20 -> 598485.66
B21: =YEAR(TODAY())+15 -> 2041 | C21: ='Reference Data'!C6+15 -> 45 | D21: =IF(C21<'Reference Data'!$C$7,'Readiness Scorecard'!$C$7,0) -> 15000 | E21: =IF(C21<'Reference Data'!$C$7,'Readiness Scorecard'!$C$8,0) -> 2250 | F21: =K20*'Reference Data'!$C$14 -> 47878.853 | G21: =K20*$I$3 -> 2992.4283 | H21: =IF(C21>='Reference Data'!$C$7,K20*$I$4,0) -> 0 | I21: =H21*0.22 -> 0 | J21: =H21-I21 -> 0 | K21: =K20+D21+E21+F21-G21-H21 -> 660622.08
B22: =YEAR(TODAY())+16 -> 2042 | C22: ='Reference Data'!C6+16 -> 46 | D22: =IF(C22<'Reference Data'!$C$7,'Readiness Scorecard'!$C$7,0) -> 15000 | E22: =IF(C22<'Reference Data'!$C$7,'Readiness Scorecard'!$C$8,0) -> 2250 | F22: =K21*'Reference Data'!$C$14 -> 52849.767 | G22: =K21*$I$3 -> 3303.1104 | H22: =IF(C22>='Reference Data'!$C$7,K21*$I$4,0) -> 0 | I22: =H22*0.22 -> 0 | J22: =H22-I22 -> 0 | K22: =K21+D22+E22+F22-G22-H22 -> 727418.74
B23: =YEAR(TODAY())+17 -> 2043 | C23: ='Reference Data'!C6+17 -> 47 | D23: =IF(C23<'Reference Data'!$C$7,'Readiness Scorecard'!$C$7,0) -> 15000 | E23: =IF(C23<'Reference Data'!$C$7,'Readiness Scorecard'!$C$8,0) -> 2250 | F23: =K22*'Reference Data'!$C$14 -> 58193.499 | G23: =K22*$I$3 -> 3637.0937 | H23: =IF(C23>='Reference Data'!$C$7,K22*$I$4,0) -> 0 | I23: =H23*0.22 -> 0 | J23: =H23-I23 -> 0 | K23: =K22+D23+E23+F23-G23-H23 -> 799225.14
B24: =YEAR(TODAY())+18 -> 2044 | C24: ='Reference Data'!C6+18 -> 48 | D24: =IF(C24<'Reference Data'!$C$7,'Readiness Scorecard'!$C$7,0) -> 15000 | E24: =IF(C24<'Reference Data'!$C$7,'Readiness Scorecard'!$C$8,0) -> 2250 | F24: =K23*'Reference Data'!$C$14 -> 63938.012 | G24: =K23*$I$3 -> 3996.1257 | H24: =IF(C24>='Reference Data'!$C$7,K23*$I$4,0) -> 0 | I24: =H24*0.22 -> 0 | J24: =H24-I24 -> 0 | K24: =K23+D24+E24+F24-G24-H24 -> 876417.03
B25: =YEAR(TODAY())+19 -> 2045 | C25: ='Reference Data'!C6+19 -> 49 | D25: =IF(C25<'Reference Data'!$C$7,'Readiness Scorecard'!$C$7,0) -> 15000 | E25: =IF(C25<'Reference Data'!$C$7,'Readiness Scorecard'!$C$8,0) -> 2250 | F25: =K24*'Reference Data'!$C$14 -> 70113.362 | G25: =K24*$I$3 -> 4382.0852 | H25: =IF(C25>='Reference Data'!$C$7,K24*$I$4,0) -> 0 | I25: =H25*0.22 -> 0 | J25: =H25-I25 -> 0 | K25: =K24+D25+E25+F25-G25-H25 -> 959398.31
B26: =YEAR(TODAY())+20 -> 2046 | C26: ='Reference Data'!C6+20 -> 50 | D26: =IF(C26<'Reference Data'!$C$7,'Readiness Scorecard'!$C$7,0) -> 15000 | E26: =IF(C26<'Reference Data'!$C$7,'Readiness Scorecard'!$C$8,0) -> 2250 | F26: =K25*'Reference Data'!$C$14 -> 76751.865 | G26: =K25*$I$3 -> 4796.9915 | H26: =IF(C26>='Reference Data'!$C$7,K25*$I$4,0) -> 0 | I26: =H26*0.22 -> 0 | J26: =H26-I26 -> 0 | K26: =K25+D26+E26+F26-G26-H26 -> 1048603.2
B27: =YEAR(TODAY())+21 -> 2047 | C27: ='Reference Data'!C6+21 -> 51 | D27: =IF(C27<'Reference Data'!$C$7,'Readiness Scorecard'!$C$7,0) -> 15000 | E27: =IF(C27<'Reference Data'!$C$7,'Readiness Scorecard'!$C$8,0) -> 2250 | F27: =K26*'Reference Data'!$C$14 -> 83888.254 | G27: =K26*$I$3 -> 5243.0159 | H27: =IF(C27>='Reference Data'!$C$7,K26*$I$4,0) -> 0 | I27: =H27*0.22 -> 0 | J27: =H27-I27 -> 0 | K27: =K26+D27+E27+F27-G27-H27 -> 1144498.4
B28: =YEAR(TODAY())+22 -> 2048 | C28: ='Reference Data'!C6+22 -> 52 | D28: =IF(C28<'Reference Data'!$C$7,'Readiness Scorecard'!$C$7,0) -> 15000 | E28: =IF(C28<'Reference Data'!$C$7,'Readiness Scorecard'!$C$8,0) -> 2250 | F28: =K27*'Reference Data'!$C$14 -> 91559.874 | G28: =K27*$I$3 -> 5722.4921 | H28: =IF(C28>='Reference Data'!$C$7,K27*$I$4,0) -> 0 | I28: =H28*0.22 -> 0 | J28: =H28-I28 -> 0 | K28: =K27+D28+E28+F28-G28-H28 -> 1247585.8
B29: =YEAR(TODAY())+23 -> 2049 | C29: ='Reference Data'!C6+23 -> 53 | D29: =IF(C29<'Reference Data'!$C$7,'Readiness Scorecard'!$C$7,0) -> 15000 | E29: =IF(C29<'Reference Data'!$C$7,'Readiness Scorecard'!$C$8,0) -> 2250 | F29: =K28*'Reference Data'!$C$14 -> 99806.864 | G29: =K28*$I$3 -> 6237.929 | H29: =IF(C29>='Reference Data'!$C$7,K28*$I$4,0) -> 0 | I29: =H29*0.22 -> 0 | J29: =H29-I29 -> 0 | K29: =K28+D29+E29+F29-G29-H29 -> 1358404.7
B30: =YEAR(TODAY())+24 -> 2050 | C30: ='Reference Data'!C6+24 -> 54 | D30: =IF(C30<'Reference Data'!$C$7,'Readiness Scorecard'!$C$7,0) -> 15000 | E30: =IF(C30<'Reference Data'!$C$7,'Readiness Scorecard'!$C$8,0) -> 2250 | F30: =K29*'Reference Data'!$C$14 -> 108672.38 | G30: =K29*$I$3 -> 6792.0237 | H30: =IF(C30>='Reference Data'!$C$7,K29*$I$4,0) -> 0 | I30: =H30*0.22 -> 0 | J30: =H30-I30 -> 0 | K30: =K29+D30+E30+F30-G30-H30 -> 1477535.1
B31: =YEAR(TODAY())+25 -> 2051 | C31: ='Reference Data'!C6+25 -> 55 | D31: =IF(C31<'Reference Data'!$C$7,'Readiness Scorecard'!$C$7,0) -> 15000 | E31: =IF(C31<'Reference Data'!$C$7,'Readiness Scorecard'!$C$8,0) -> 2250 | F31: =K30*'Reference Data'!$C$14 -> 118202.81 | G31: =K30*$I$3 -> 7387.6755 | H31: =IF(C31>='Reference Data'!$C$7,K30*$I$4,0) -> 0 | I31: =H31*0.22 -> 0 | J31: =H31-I31 -> 0 | K31: =K30+D31+E31+F31-G31-H31 -> 1605600.2
B32: =YEAR(TODAY())+26 -> 2052 | C32: ='Reference Data'!C6+26 -> 56 | D32: =IF(C32<'Reference Data'!$C$7,'Readiness Scorecard'!$C$7,0) -> 15000 | E32: =IF(C32<'Reference Data'!$C$7,'Readiness Scorecard'!$C$8,0) -> 2250 | F32: =K31*'Reference Data'!$C$14 -> 128448.02 | G32: =K31*$I$3 -> 8028.0011 | H32: =IF(C32>='Reference Data'!$C$7,K31*$I$4,0) -> 0 | I32: =H32*0.22 -> 0 | J32: =H32-I32 -> 0 | K32: =K31+D32+E32+F32-G32-H32 -> 1743270.2
B33: =YEAR(TODAY())+27 -> 2053 | C33: ='Reference Data'!C6+27 -> 57 | D33: =IF(C33<'Reference Data'!$C$7,'Readiness Scorecard'!$C$7,0) -> 15000 | E33: =IF(C33<'Reference Data'!$C$7,'Readiness Scorecard'!$C$8,0) -> 2250 | F33: =K32*'Reference Data'!$C$14 -> 139461.62 | G33: =K32*$I$3 -> 8716.3512 | H33: =IF(C33>='Reference Data'!$C$7,K32*$I$4,0) -> 0 | I33: =H33*0.22 -> 0 | J33: =H33-I33 -> 0 | K33: =K32+D33+E33+F33-G33-H33 -> 1891265.5
B34: =YEAR(TODAY())+28 -> 2054 | C34: ='Reference Data'!C6+28 -> 58 | D34: =IF(C34<'Reference Data'!$C$7,'Readiness Scorecard'!$C$7,0) -> 15000 | E34: =IF(C34<'Reference Data'!$C$7,'Readiness Scorecard'!$C$8,0) -> 2250 | F34: =K33*'Reference Data'!$C$14 -> 151301.24 | G34: =K33*$I$3 -> 9456.3275 | H34: =IF(C34>='Reference Data'!$C$7,K33*$I$4,0) -> 0 | I34: =H34*0.22 -> 0 | J34: =H34-I34 -> 0 | K34: =K33+D34+E34+F34-G34-H34 -> 2050360.4
B35: =YEAR(TODAY())+29 -> 2055 | C35: ='Reference Data'!C6+29 -> 59 | D35: =IF(C35<'Reference Data'!$C$7,'Readiness Scorecard'!$C$7,0) -> 15000 | E35: =IF(C35<'Reference Data'!$C$7,'Readiness Scorecard'!$C$8,0) -> 2250 | F35: =K34*'Reference Data'!$C$14 -> 164028.83 | G35: =K34*$I$3 -> 10251.802 | H35: =IF(C35>='Reference Data'!$C$7,K34*$I$4,0) -> 0 | I35: =H35*0.22 -> 0 | J35: =H35-I35 -> 0 | K35: =K34+D35+E35+F35-G35-H35 -> 2221387.5
B36: =YEAR(TODAY())+30 -> 2056 | C36: ='Reference Data'!C6+30 -> 60 | D36: =IF(C36<'Reference Data'!$C$7,'Readiness Scorecard'!$C$7,0) -> 15000 | E36: =IF(C36<'Reference Data'!$C$7,'Readiness Scorecard'!$C$8,0) -> 2250 | F36: =K35*'Reference Data'!$C$14 -> 177711 | G36: =K35*$I$3 -> 11106.937 | H36: =IF(C36>='Reference Data'!$C$7,K35*$I$4,0) -> 0 | I36: =H36*0.22 -> 0 | J36: =H36-I36 -> 0 | K36: =K35+D36+E36+F36-G36-H36 -> 2405241.5
B37: =YEAR(TODAY())+31 -> 2057 | C37: ='Reference Data'!C6+31 -> 61 | D37: =IF(C37<'Reference Data'!$C$7,'Readiness Scorecard'!$C$7,0) -> 15000 | E37: =IF(C37<'Reference Data'!$C$7,'Readiness Scorecard'!$C$8,0) -> 2250 | F37: =K36*'Reference Data'!$C$14 -> 192419.32 | G37: =K36*$I$3 -> 12026.208 | H37: =IF(C37>='Reference Data'!$C$7,K36*$I$4,0) -> 0 | I37: =H37*0.22 -> 0 | J37: =H37-I37 -> 0 | K37: =K36+D37+E37+F37-G37-H37 -> 2602884.6
B38: =YEAR(TODAY())+32 -> 2058 | C38: ='Reference Data'!C6+32 -> 62 | D38: =IF(C38<'Reference Data'!$C$7,'Readiness Scorecard'!$C$7,0) -> 15000 | E38: =IF(C38<'Reference Data'!$C$7,'Readiness Scorecard'!$C$8,0) -> 2250 | F38: =K37*'Reference Data'!$C$14 -> 208230.77 | G38: =K37*$I$3 -> 13014.423 | H38: =IF(C38>='Reference Data'!$C$7,K37*$I$4,0) -> 0 | I38: =H38*0.22 -> 0 | J38: =H38-I38 -> 0 | K38: =K37+D38+E38+F38-G38-H38 -> 2815351
B39: =YEAR(TODAY())+33 -> 2059 | C39: ='Reference Data'!C6+33 -> 63 | D39: =IF(C39<'Reference Data'!$C$7,'Readiness Scorecard'!$C$7,0) -> 15000 | E39: =IF(C39<'Reference Data'!$C$7,'Readiness Scorecard'!$C$8,0) -> 2250 | F39: =K38*'Reference Data'!$C$14 -> 225228.08 | G39: =K38*$I$3 -> 14076.755 | H39: =IF(C39>='Reference Data'!$C$7,K38*$I$4,0) -> 0 | I39: =H39*0.22 -> 0 | J39: =H39-I39 -> 0 | K39: =K38+D39+E39+F39-G39-H39 -> 3043752.3
B40: =YEAR(TODAY())+34 -> 2060 | C40: ='Reference Data'!C6+34 -> 64 | D40: =IF(C40<'Reference Data'!$C$7,'Readiness Scorecard'!$C$7,0) -> 15000 | E40: =IF(C40<'Reference Data'!$C$7,'Readiness Scorecard'!$C$8,0) -> 2250 | F40: =K39*'Reference Data'!$C$14 -> 243500.18 | G40: =K39*$I$3 -> 15218.761 | H40: =IF(C40>='Reference Data'!$C$7,K39*$I$4,0) -> 0 | I40: =H40*0.22 -> 0 | J40: =H40-I40 -> 0 | K40: =K39+D40+E40+F40-G40-H40 -> 3289283.7
B41: =YEAR(TODAY())+35 -> 2061 | C41: ='Reference Data'!C6+35 -> 65 | D41: =IF(C41<'Reference Data'!$C$7,'Readiness Scorecard'!$C$7,0) -> 0 | E41: =IF(C41<'Reference Data'!$C$7,'Readiness Scorecard'!$C$8,0) -> 0 | F41: =K40*'Reference Data'!$C$14 -> 263142.7 | G41: =K40*$I$3 -> 16446.419 | H41: =IF(C41>='Reference Data'!$C$7,K40*$I$4,0) -> 131571.35 | I41: =H41*0.22 -> 28945.697 | J41: =H41-I41 -> 102625.65 | K41: =K40+D41+E41+F41-G41-H41 -> 3404408.6
...
